TODO:Error en create.all() - categooria.py

Ese error parece estar ocurriendo en una aplicación que está utilizando SQLAlchemy (o una biblioteca como Flask-SQLAlchemy) y se relaciona con la función `create_all()`, que se usa para crear todas las tablas definidas en los modelos de la base de datos.

El mensaje `self._call_for_binds(bind_key, "create_all")` sugiere que hay un problema al intentar aplicar `create_all()` a una conexión/bind específica de la base de datos.

---

### Posibles causas del error

1. **`bind_key` no definido correctamente**  
   Si estás usando múltiples conexiones (binds), necesitas especificar `bind_key` en tus modelos y también definir los binds en la configuración de SQLAlchemy, como por ejemplo:

   ```python
   SQLALCHEMY_BINDS = {
       'users':        'sqlite:///users.db',
       'appmeta':      'sqlite:///appmeta.db'
   }
   ```

   Y en tus modelos:

   ```python
   class User(db.Model):
       __bind_key__ = 'users'
       ...
   ```

2. **`create_all()` se está llamando sin contexto de aplicación** (si usas Flask)  
   Asegúrate de que estás ejecutando `create_all()` dentro del contexto de la aplicación:

   ```python
   with app.app_context():
       db.create_all()
   ```

3. **Error de importación o mal uso del `db`**  
   Verifica que estás llamando `db.create_all()` desde el objeto `db` correcto, y que no tienes conflictos de nombres o problemas de importación.

---

### Para ayudarte mejor...

¿Puedes compartir un poco más del traceback del error y cómo estás llamando `create_all()`? Especialmente:

- Parte del código donde llamas `create_all()`
- Si usas Flask, tu configuración de `app` y `db`
- Si usas `__bind_key__`, cómo lo tienes definido

Con eso puedo darte una solución exacta 😄